2020-10-08 10:25:03,273 INFO Sensor Configured Successfully
2020-10-08 10:26:32,032 INFO Sensor Configured Successfully
2020-10-08 10:26:32,036 INFO Worker initialized
2020-10-08 10:26:32,178 INFO Worker Working
2020-10-08 10:31:01,873 INFO Worker initialized
2020-10-08 10:31:02,009 INFO Worker Working
2020-10-08 10:36:04,728 INFO Worker initialized
2020-10-08 10:36:04,873 INFO Worker Working
2020-10-08 10:39:26,718 INFO Worker initialized
2020-10-08 10:39:26,862 INFO Worker Working
2020-10-08 12:09:05,411 INFO Worker initialized
2020-10-08 12:09:05,550 INFO Worker Working
2020-10-08 12:11:13,566 INFO Worker initialized
2020-10-08 12:11:13,699 INFO Worker Working
2020-10-08 12:11:41,060 INFO Worker initialized
2020-10-08 12:11:41,193 INFO Worker Working
2020-10-08 16:27:23,908 INFO Worker initialized
2020-10-08 16:27:24,043 INFO Worker Working
2020-10-08 16:31:25,491 INFO Worker initialized
2020-10-08 16:31:25,626 INFO Worker Working
2020-10-08 16:32:31,154 INFO Worker initialized
2020-10-08 16:32:31,288 INFO Worker Working
2020-10-08 16:33:39,487 INFO Worker initialized
2020-10-08 16:33:39,632 INFO Worker Working
2020-10-08 16:34:41,867 INFO Worker initialized
2020-10-08 16:34:42,006 INFO Worker Working
2020-10-08 16:37:17,976 INFO Worker initialized
2020-10-08 16:37:18,103 INFO Worker Working
2020-10-08 16:38:31,617 INFO Worker initialized
2020-10-08 16:38:31,752 INFO Worker Working
2020-10-08 16:39:45,345 INFO Worker initialized
2020-10-08 16:39:45,480 INFO Worker Working
2020-10-08 16:40:41,343 INFO Worker initialized
2020-10-08 16:40:41,477 INFO Worker Working
2020-10-13 15:03:25,670 INFO Worker initialized
2020-10-13 15:03:25,808 INFO Worker Working
2020-10-14 10:56:05,929 ERROR Serial Exception while initializing worker
Traceback (most recent call last):
  File "/home/jetsonuser/.local/lib/python3.6/site-packages/serial/serialposix.py", line 265, in open
    self.fd = os.open(self.portstr, os.O_RDWR | os.O_NOCTTY | os.O_NONBLOCK)
FileNotFoundError: [Errno 2] No such file or directory: '/dev/ttyACM0'

During handling of the above exception, another exception occurred:

Traceback (most recent call last):
  File "/opt/nvidia/deepstream/deepstream-5.0/sources/deepstream_python_apps/apps/tdfflask/tdfmotorway/processes/radar/SpeedWorker1_0.py", line 19, in __init__
    self.serial_port=serial.Serial(self.port,baudrate=int(self.baud_rate))
  File "/home/jetsonuser/.local/lib/python3.6/site-packages/serial/serialutil.py", line 240, in __init__
    self.open()
  File "/home/jetsonuser/.local/lib/python3.6/site-packages/serial/serialposix.py", line 268, in open
    raise SerialException(msg.errno, "could not open port {}: {}".format(self._port, msg))
serial.serialutil.SerialException: [Errno 2] could not open port /dev/ttyACM0: [Errno 2] No such file or directory: '/dev/ttyACM0'
2020-10-14 10:56:05,944 INFO Worker Working
2020-10-14 10:57:04,122 ERROR Serial Exception while initializing worker
Traceback (most recent call last):
  File "/home/jetsonuser/.local/lib/python3.6/site-packages/serial/serialposix.py", line 265, in open
    self.fd = os.open(self.portstr, os.O_RDWR | os.O_NOCTTY | os.O_NONBLOCK)
FileNotFoundError: [Errno 2] No such file or directory: '/dev/ttyACM0'

During handling of the above exception, another exception occurred:

Traceback (most recent call last):
  File "/opt/nvidia/deepstream/deepstream-5.0/sources/deepstream_python_apps/apps/tdfflask/tdfmotorway/processes/radar/SpeedWorker1_0.py", line 19, in __init__
    self.serial_port=serial.Serial(self.port,baudrate=int(self.baud_rate))
  File "/home/jetsonuser/.local/lib/python3.6/site-packages/serial/serialutil.py", line 240, in __init__
    self.open()
  File "/home/jetsonuser/.local/lib/python3.6/site-packages/serial/serialposix.py", line 268, in open
    raise SerialException(msg.errno, "could not open port {}: {}".format(self._port, msg))
serial.serialutil.SerialException: [Errno 2] could not open port /dev/ttyACM0: [Errno 2] No such file or directory: '/dev/ttyACM0'
2020-10-14 10:57:04,139 INFO Worker Working
2020-10-14 10:59:07,502 ERROR Serial Exception while initializing worker
Traceback (most recent call last):
  File "/home/jetsonuser/.local/lib/python3.6/site-packages/serial/serialposix.py", line 265, in open
    self.fd = os.open(self.portstr, os.O_RDWR | os.O_NOCTTY | os.O_NONBLOCK)
FileNotFoundError: [Errno 2] No such file or directory: '/dev/ttyACM0'

During handling of the above exception, another exception occurred:

Traceback (most recent call last):
  File "/opt/nvidia/deepstream/deepstream-5.0/sources/deepstream_python_apps/apps/tdfflask/tdfmotorway/processes/radar/SpeedWorker1_0.py", line 19, in __init__
    self.serial_port=serial.Serial(self.port,baudrate=int(self.baud_rate))
  File "/home/jetsonuser/.local/lib/python3.6/site-packages/serial/serialutil.py", line 240, in __init__
    self.open()
  File "/home/jetsonuser/.local/lib/python3.6/site-packages/serial/serialposix.py", line 268, in open
    raise SerialException(msg.errno, "could not open port {}: {}".format(self._port, msg))
serial.serialutil.SerialException: [Errno 2] could not open port /dev/ttyACM0: [Errno 2] No such file or directory: '/dev/ttyACM0'
2020-10-14 10:59:07,518 INFO Worker Working
2020-10-14 11:00:40,462 ERROR Serial Exception while initializing worker
Traceback (most recent call last):
  File "/home/jetsonuser/.local/lib/python3.6/site-packages/serial/serialposix.py", line 265, in open
    self.fd = os.open(self.portstr, os.O_RDWR | os.O_NOCTTY | os.O_NONBLOCK)
FileNotFoundError: [Errno 2] No such file or directory: '/dev/ttyACM0'

During handling of the above exception, another exception occurred:

Traceback (most recent call last):
  File "/opt/nvidia/deepstream/deepstream-5.0/sources/deepstream_python_apps/apps/tdfflask/tdfmotorway/processes/radar/SpeedWorker1_0.py", line 19, in __init__
    self.serial_port=serial.Serial(self.port,baudrate=int(self.baud_rate))
  File "/home/jetsonuser/.local/lib/python3.6/site-packages/serial/serialutil.py", line 240, in __init__
    self.open()
  File "/home/jetsonuser/.local/lib/python3.6/site-packages/serial/serialposix.py", line 268, in open
    raise SerialException(msg.errno, "could not open port {}: {}".format(self._port, msg))
serial.serialutil.SerialException: [Errno 2] could not open port /dev/ttyACM0: [Errno 2] No such file or directory: '/dev/ttyACM0'
2020-10-14 11:00:40,480 INFO Worker Working
2020-10-14 11:02:06,378 ERROR Serial Exception while initializing worker
Traceback (most recent call last):
  File "/home/jetsonuser/.local/lib/python3.6/site-packages/serial/serialposix.py", line 265, in open
    self.fd = os.open(self.portstr, os.O_RDWR | os.O_NOCTTY | os.O_NONBLOCK)
FileNotFoundError: [Errno 2] No such file or directory: '/dev/ttyACM0'

During handling of the above exception, another exception occurred:

Traceback (most recent call last):
  File "/opt/nvidia/deepstream/deepstream-5.0/sources/deepstream_python_apps/apps/tdfflask/tdfmotorway/processes/radar/SpeedWorker1_0.py", line 19, in __init__
    self.serial_port=serial.Serial(self.port,baudrate=int(self.baud_rate))
  File "/home/jetsonuser/.local/lib/python3.6/site-packages/serial/serialutil.py", line 240, in __init__
    self.open()
  File "/home/jetsonuser/.local/lib/python3.6/site-packages/serial/serialposix.py", line 268, in open
    raise SerialException(msg.errno, "could not open port {}: {}".format(self._port, msg))
serial.serialutil.SerialException: [Errno 2] could not open port /dev/ttyACM0: [Errno 2] No such file or directory: '/dev/ttyACM0'
2020-10-14 11:02:06,395 INFO Worker Working
2020-10-14 11:03:42,424 ERROR Serial Exception while initializing worker
Traceback (most recent call last):
  File "/home/jetsonuser/.local/lib/python3.6/site-packages/serial/serialposix.py", line 265, in open
    self.fd = os.open(self.portstr, os.O_RDWR | os.O_NOCTTY | os.O_NONBLOCK)
FileNotFoundError: [Errno 2] No such file or directory: '/dev/ttyACM0'

During handling of the above exception, another exception occurred:

Traceback (most recent call last):
  File "/opt/nvidia/deepstream/deepstream-5.0/sources/deepstream_python_apps/apps/tdfflask/tdfmotorway/processes/radar/SpeedWorker1_0.py", line 19, in __init__
    self.serial_port=serial.Serial(self.port,baudrate=int(self.baud_rate))
  File "/home/jetsonuser/.local/lib/python3.6/site-packages/serial/serialutil.py", line 240, in __init__
    self.open()
  File "/home/jetsonuser/.local/lib/python3.6/site-packages/serial/serialposix.py", line 268, in open
    raise SerialException(msg.errno, "could not open port {}: {}".format(self._port, msg))
serial.serialutil.SerialException: [Errno 2] could not open port /dev/ttyACM0: [Errno 2] No such file or directory: '/dev/ttyACM0'
2020-10-14 11:03:42,441 INFO Worker Working
2020-10-14 11:04:01,661 ERROR Serial Exception while initializing worker
Traceback (most recent call last):
  File "/home/jetsonuser/.local/lib/python3.6/site-packages/serial/serialposix.py", line 265, in open
    self.fd = os.open(self.portstr, os.O_RDWR | os.O_NOCTTY | os.O_NONBLOCK)
FileNotFoundError: [Errno 2] No such file or directory: '/dev/ttyACM0'

During handling of the above exception, another exception occurred:

Traceback (most recent call last):
  File "/opt/nvidia/deepstream/deepstream-5.0/sources/deepstream_python_apps/apps/tdfflask/tdfmotorway/processes/radar/SpeedWorker1_0.py", line 19, in __init__
    self.serial_port=serial.Serial(self.port,baudrate=int(self.baud_rate))
  File "/home/jetsonuser/.local/lib/python3.6/site-packages/serial/serialutil.py", line 240, in __init__
    self.open()
  File "/home/jetsonuser/.local/lib/python3.6/site-packages/serial/serialposix.py", line 268, in open
    raise SerialException(msg.errno, "could not open port {}: {}".format(self._port, msg))
serial.serialutil.SerialException: [Errno 2] could not open port /dev/ttyACM0: [Errno 2] No such file or directory: '/dev/ttyACM0'
2020-10-14 11:04:01,676 INFO Worker Working
2020-10-14 11:04:36,745 ERROR Serial Exception while initializing worker
Traceback (most recent call last):
  File "/home/jetsonuser/.local/lib/python3.6/site-packages/serial/serialposix.py", line 265, in open
    self.fd = os.open(self.portstr, os.O_RDWR | os.O_NOCTTY | os.O_NONBLOCK)
FileNotFoundError: [Errno 2] No such file or directory: '/dev/ttyACM0'

During handling of the above exception, another exception occurred:

Traceback (most recent call last):
  File "/opt/nvidia/deepstream/deepstream-5.0/sources/deepstream_python_apps/apps/tdfflask/tdfmotorway/processes/radar/SpeedWorker1_0.py", line 19, in __init__
    self.serial_port=serial.Serial(self.port,baudrate=int(self.baud_rate))
  File "/home/jetsonuser/.local/lib/python3.6/site-packages/serial/serialutil.py", line 240, in __init__
    self.open()
  File "/home/jetsonuser/.local/lib/python3.6/site-packages/serial/serialposix.py", line 268, in open
    raise SerialException(msg.errno, "could not open port {}: {}".format(self._port, msg))
serial.serialutil.SerialException: [Errno 2] could not open port /dev/ttyACM0: [Errno 2] No such file or directory: '/dev/ttyACM0'
2020-10-14 11:04:36,762 INFO Worker Working
2020-10-14 11:05:15,928 ERROR Serial Exception while initializing worker
Traceback (most recent call last):
  File "/home/jetsonuser/.local/lib/python3.6/site-packages/serial/serialposix.py", line 265, in open
    self.fd = os.open(self.portstr, os.O_RDWR | os.O_NOCTTY | os.O_NONBLOCK)
FileNotFoundError: [Errno 2] No such file or directory: '/dev/ttyACM0'

During handling of the above exception, another exception occurred:

Traceback (most recent call last):
  File "/opt/nvidia/deepstream/deepstream-5.0/sources/deepstream_python_apps/apps/tdfflask/tdfmotorway/processes/radar/SpeedWorker1_0.py", line 19, in __init__
    self.serial_port=serial.Serial(self.port,baudrate=int(self.baud_rate))
  File "/home/jetsonuser/.local/lib/python3.6/site-packages/serial/serialutil.py", line 240, in __init__
    self.open()
  File "/home/jetsonuser/.local/lib/python3.6/site-packages/serial/serialposix.py", line 268, in open
    raise SerialException(msg.errno, "could not open port {}: {}".format(self._port, msg))
serial.serialutil.SerialException: [Errno 2] could not open port /dev/ttyACM0: [Errno 2] No such file or directory: '/dev/ttyACM0'
2020-10-14 11:05:15,943 INFO Worker Working
2020-10-14 11:07:20,109 ERROR Serial Exception while initializing worker
Traceback (most recent call last):
  File "/home/jetsonuser/.local/lib/python3.6/site-packages/serial/serialposix.py", line 265, in open
    self.fd = os.open(self.portstr, os.O_RDWR | os.O_NOCTTY | os.O_NONBLOCK)
FileNotFoundError: [Errno 2] No such file or directory: '/dev/ttyACM0'

During handling of the above exception, another exception occurred:

Traceback (most recent call last):
  File "/opt/nvidia/deepstream/deepstream-5.0/sources/deepstream_python_apps/apps/tdfflask/tdfmotorway/processes/radar/SpeedWorker1_0.py", line 19, in __init__
    self.serial_port=serial.Serial(self.port,baudrate=int(self.baud_rate))
  File "/home/jetsonuser/.local/lib/python3.6/site-packages/serial/serialutil.py", line 240, in __init__
    self.open()
  File "/home/jetsonuser/.local/lib/python3.6/site-packages/serial/serialposix.py", line 268, in open
    raise SerialException(msg.errno, "could not open port {}: {}".format(self._port, msg))
serial.serialutil.SerialException: [Errno 2] could not open port /dev/ttyACM0: [Errno 2] No such file or directory: '/dev/ttyACM0'
2020-10-14 11:07:20,123 INFO Worker Working
2020-10-14 11:11:34,051 ERROR Serial Exception while initializing worker
Traceback (most recent call last):
  File "/home/jetsonuser/.local/lib/python3.6/site-packages/serial/serialposix.py", line 265, in open
    self.fd = os.open(self.portstr, os.O_RDWR | os.O_NOCTTY | os.O_NONBLOCK)
FileNotFoundError: [Errno 2] No such file or directory: '/dev/ttyACM0'

During handling of the above exception, another exception occurred:

Traceback (most recent call last):
  File "/opt/nvidia/deepstream/deepstream-5.0/sources/deepstream_python_apps/apps/tdfflask/tdfmotorway/processes/radar/SpeedWorker1_0.py", line 19, in __init__
    self.serial_port=serial.Serial(self.port,baudrate=int(self.baud_rate))
  File "/home/jetsonuser/.local/lib/python3.6/site-packages/serial/serialutil.py", line 240, in __init__
    self.open()
  File "/home/jetsonuser/.local/lib/python3.6/site-packages/serial/serialposix.py", line 268, in open
    raise SerialException(msg.errno, "could not open port {}: {}".format(self._port, msg))
serial.serialutil.SerialException: [Errno 2] could not open port /dev/ttyACM0: [Errno 2] No such file or directory: '/dev/ttyACM0'
2020-10-14 11:11:34,068 INFO Worker Working
2020-10-14 11:24:22,787 ERROR Serial Exception while initializing worker
Traceback (most recent call last):
  File "/home/jetsonuser/.local/lib/python3.6/site-packages/serial/serialposix.py", line 265, in open
    self.fd = os.open(self.portstr, os.O_RDWR | os.O_NOCTTY | os.O_NONBLOCK)
FileNotFoundError: [Errno 2] No such file or directory: '/dev/ttyACM0'

During handling of the above exception, another exception occurred:

Traceback (most recent call last):
  File "/opt/nvidia/deepstream/deepstream-5.0/sources/deepstream_python_apps/apps/tdfflask/tdfmotorway/processes/radar/SpeedWorker1_0.py", line 19, in __init__
    self.serial_port=serial.Serial(self.port,baudrate=int(self.baud_rate))
  File "/home/jetsonuser/.local/lib/python3.6/site-packages/serial/serialutil.py", line 240, in __init__
    self.open()
  File "/home/jetsonuser/.local/lib/python3.6/site-packages/serial/serialposix.py", line 268, in open
    raise SerialException(msg.errno, "could not open port {}: {}".format(self._port, msg))
serial.serialutil.SerialException: [Errno 2] could not open port /dev/ttyACM0: [Errno 2] No such file or directory: '/dev/ttyACM0'
2020-10-14 11:24:22,804 INFO Worker Working
2020-10-14 11:29:42,123 ERROR Serial Exception while initializing worker
Traceback (most recent call last):
  File "/home/jetsonuser/.local/lib/python3.6/site-packages/serial/serialposix.py", line 265, in open
    self.fd = os.open(self.portstr, os.O_RDWR | os.O_NOCTTY | os.O_NONBLOCK)
FileNotFoundError: [Errno 2] No such file or directory: '/dev/ttyACM0'

During handling of the above exception, another exception occurred:

Traceback (most recent call last):
  File "/opt/nvidia/deepstream/deepstream-5.0/sources/deepstream_python_apps/apps/tdfflask/tdfmotorway/processes/radar/SpeedWorker1_0.py", line 19, in __init__
    self.serial_port=serial.Serial(self.port,baudrate=int(self.baud_rate))
  File "/home/jetsonuser/.local/lib/python3.6/site-packages/serial/serialutil.py", line 240, in __init__
    self.open()
  File "/home/jetsonuser/.local/lib/python3.6/site-packages/serial/serialposix.py", line 268, in open
    raise SerialException(msg.errno, "could not open port {}: {}".format(self._port, msg))
serial.serialutil.SerialException: [Errno 2] could not open port /dev/ttyACM0: [Errno 2] No such file or directory: '/dev/ttyACM0'
2020-10-14 11:29:42,142 INFO Worker Working
2020-10-14 12:37:30,301 ERROR Serial Exception while initializing worker
Traceback (most recent call last):
  File "/home/jetsonuser/.local/lib/python3.6/site-packages/serial/serialposix.py", line 265, in open
    self.fd = os.open(self.portstr, os.O_RDWR | os.O_NOCTTY | os.O_NONBLOCK)
FileNotFoundError: [Errno 2] No such file or directory: '/dev/ttyACM0'

During handling of the above exception, another exception occurred:

Traceback (most recent call last):
  File "/opt/nvidia/deepstream/deepstream-5.0/sources/deepstream_python_apps/apps/tdfflask/tdfmotorway/processes/radar/SpeedWorker1_0.py", line 19, in __init__
    self.serial_port=serial.Serial(self.port,baudrate=int(self.baud_rate))
  File "/home/jetsonuser/.local/lib/python3.6/site-packages/serial/serialutil.py", line 240, in __init__
    self.open()
  File "/home/jetsonuser/.local/lib/python3.6/site-packages/serial/serialposix.py", line 268, in open
    raise SerialException(msg.errno, "could not open port {}: {}".format(self._port, msg))
serial.serialutil.SerialException: [Errno 2] could not open port /dev/ttyACM0: [Errno 2] No such file or directory: '/dev/ttyACM0'
2020-10-14 12:37:30,318 INFO Worker Working
2020-10-14 12:39:25,373 ERROR Serial Exception while initializing worker
Traceback (most recent call last):
  File "/home/jetsonuser/.local/lib/python3.6/site-packages/serial/serialposix.py", line 265, in open
    self.fd = os.open(self.portstr, os.O_RDWR | os.O_NOCTTY | os.O_NONBLOCK)
FileNotFoundError: [Errno 2] No such file or directory: '/dev/ttyACM0'

During handling of the above exception, another exception occurred:

Traceback (most recent call last):
  File "/opt/nvidia/deepstream/deepstream-5.0/sources/deepstream_python_apps/apps/tdfflask/tdfmotorway/processes/radar/SpeedWorker1_0.py", line 19, in __init__
    self.serial_port=serial.Serial(self.port,baudrate=int(self.baud_rate))
  File "/home/jetsonuser/.local/lib/python3.6/site-packages/serial/serialutil.py", line 240, in __init__
    self.open()
  File "/home/jetsonuser/.local/lib/python3.6/site-packages/serial/serialposix.py", line 268, in open
    raise SerialException(msg.errno, "could not open port {}: {}".format(self._port, msg))
serial.serialutil.SerialException: [Errno 2] could not open port /dev/ttyACM0: [Errno 2] No such file or directory: '/dev/ttyACM0'
2020-10-14 12:39:25,395 INFO Worker Working
2020-10-14 12:40:27,586 ERROR Serial Exception while initializing worker
Traceback (most recent call last):
  File "/home/jetsonuser/.local/lib/python3.6/site-packages/serial/serialposix.py", line 265, in open
    self.fd = os.open(self.portstr, os.O_RDWR | os.O_NOCTTY | os.O_NONBLOCK)
FileNotFoundError: [Errno 2] No such file or directory: '/dev/ttyACM0'

During handling of the above exception, another exception occurred:

Traceback (most recent call last):
  File "/opt/nvidia/deepstream/deepstream-5.0/sources/deepstream_python_apps/apps/tdfflask/tdfmotorway/processes/radar/SpeedWorker1_0.py", line 19, in __init__
    self.serial_port=serial.Serial(self.port,baudrate=int(self.baud_rate))
  File "/home/jetsonuser/.local/lib/python3.6/site-packages/serial/serialutil.py", line 240, in __init__
    self.open()
  File "/home/jetsonuser/.local/lib/python3.6/site-packages/serial/serialposix.py", line 268, in open
    raise SerialException(msg.errno, "could not open port {}: {}".format(self._port, msg))
serial.serialutil.SerialException: [Errno 2] could not open port /dev/ttyACM0: [Errno 2] No such file or directory: '/dev/ttyACM0'
2020-10-14 12:40:27,604 INFO Worker Working
2020-10-14 12:52:00,511 ERROR Serial Exception while initializing worker
Traceback (most recent call last):
  File "/home/jetsonuser/.local/lib/python3.6/site-packages/serial/serialposix.py", line 265, in open
    self.fd = os.open(self.portstr, os.O_RDWR | os.O_NOCTTY | os.O_NONBLOCK)
FileNotFoundError: [Errno 2] No such file or directory: '/dev/ttyACM0'

During handling of the above exception, another exception occurred:

Traceback (most recent call last):
  File "/opt/nvidia/deepstream/deepstream-5.0/sources/deepstream_python_apps/apps/tdfflask/tdfmotorway/processes/radar/SpeedWorker1_0.py", line 19, in __init__
    self.serial_port=serial.Serial(self.port,baudrate=int(self.baud_rate))
  File "/home/jetsonuser/.local/lib/python3.6/site-packages/serial/serialutil.py", line 240, in __init__
    self.open()
  File "/home/jetsonuser/.local/lib/python3.6/site-packages/serial/serialposix.py", line 268, in open
    raise SerialException(msg.errno, "could not open port {}: {}".format(self._port, msg))
serial.serialutil.SerialException: [Errno 2] could not open port /dev/ttyACM0: [Errno 2] No such file or directory: '/dev/ttyACM0'
2020-10-14 12:52:00,530 INFO Worker Working
2020-10-14 12:56:48,271 ERROR Serial Exception while initializing worker
Traceback (most recent call last):
  File "/home/jetsonuser/.local/lib/python3.6/site-packages/serial/serialposix.py", line 265, in open
    self.fd = os.open(self.portstr, os.O_RDWR | os.O_NOCTTY | os.O_NONBLOCK)
FileNotFoundError: [Errno 2] No such file or directory: '/dev/ttyACM0'

During handling of the above exception, another exception occurred:

Traceback (most recent call last):
  File "/opt/nvidia/deepstream/deepstream-5.0/sources/deepstream_python_apps/apps/tdfflask/tdfmotorway/processes/radar/SpeedWorker1_0.py", line 19, in __init__
    self.serial_port=serial.Serial(self.port,baudrate=int(self.baud_rate))
  File "/home/jetsonuser/.local/lib/python3.6/site-packages/serial/serialutil.py", line 240, in __init__
    self.open()
  File "/home/jetsonuser/.local/lib/python3.6/site-packages/serial/serialposix.py", line 268, in open
    raise SerialException(msg.errno, "could not open port {}: {}".format(self._port, msg))
serial.serialutil.SerialException: [Errno 2] could not open port /dev/ttyACM0: [Errno 2] No such file or directory: '/dev/ttyACM0'
2020-10-14 12:56:48,285 INFO Worker Working
2020-10-14 12:58:24,308 INFO Worker initialized
2020-10-14 12:58:24,331 INFO Worker Working
2020-10-14 12:59:56,851 INFO Worker initialized
2020-10-14 12:59:57,001 INFO Worker Working
2020-10-14 13:01:58,144 INFO Worker initialized
2020-10-14 13:01:58,275 INFO Worker Working
2020-10-14 13:03:16,309 INFO Worker initialized
2020-10-14 13:03:16,445 INFO Worker Working
2020-10-14 13:03:51,766 INFO Worker initialized
2020-10-14 13:03:51,905 INFO Worker Working
2020-10-14 13:05:21,122 INFO Worker initialized
2020-10-14 13:05:21,264 INFO Worker Working
2020-10-14 13:06:43,845 INFO Worker initialized
2020-10-14 13:06:43,985 INFO Worker Working
2020-10-14 13:06:43,989 ERROR Error while decoding JSON string in worker
Traceback (most recent call last):
  File "/opt/nvidia/deepstream/deepstream-5.0/sources/deepstream_python_apps/apps/tdfflask/tdfmotorway/processes/radar/SpeedWorker1_0.py", line 49, in process_speed
    ndata=json.loads(x)
  File "/usr/lib/python3.6/json/__init__.py", line 354, in loads
    return _default_decoder.decode(s)
  File "/usr/lib/python3.6/json/decoder.py", line 342, in decode
    raise JSONDecodeError("Extra data", s, end)
json.decoder.JSONDecodeError: Extra data: line 1 column 6 (char 5)
2020-10-14 13:07:59,922 INFO Worker initialized
2020-10-14 13:08:00,062 INFO Worker Working
2020-10-14 13:11:15,258 INFO Worker initialized
2020-10-14 13:11:15,391 INFO Worker Working
2020-10-14 13:12:31,057 INFO Worker initialized
2020-10-14 13:12:31,193 INFO Worker Working
2020-10-14 15:23:40,186 INFO Worker initialized
2020-10-14 15:23:40,320 INFO Worker Working
2020-10-14 15:26:14,185 INFO Worker initialized
2020-10-14 15:26:14,315 INFO Worker Working
2020-10-14 15:30:04,822 INFO Worker initialized
2020-10-14 15:30:04,948 INFO Worker Working
2020-10-14 15:32:24,866 INFO Worker initialized
2020-10-14 15:32:25,002 INFO Worker Working
2020-10-14 15:34:48,306 INFO Worker initialized
2020-10-14 15:34:48,439 INFO Worker Working
2020-10-14 15:56:38,517 INFO Worker initialized
2020-10-14 15:56:38,653 INFO Worker Working
2020-10-14 16:03:04,791 INFO Worker initialized
2020-10-14 16:03:04,927 INFO Worker Working
2020-10-14 16:05:15,798 INFO Worker initialized
2020-10-14 16:05:15,937 INFO Worker Working
2020-10-14 16:15:04,278 INFO Worker initialized
2020-10-14 16:15:04,413 INFO Worker Working
2020-10-14 16:27:47,052 INFO Worker initialized
2020-10-14 16:27:47,186 INFO Worker Working
2020-10-14 16:29:43,840 INFO Worker initialized
2020-10-14 16:29:43,974 INFO Worker Working
2020-10-14 16:31:47,034 INFO Worker initialized
2020-10-14 16:31:47,172 INFO Worker Working
2020-10-14 16:34:43,316 INFO Worker initialized
2020-10-14 16:34:43,456 INFO Worker Working
2020-10-14 16:35:38,353 INFO Worker initialized
2020-10-14 16:35:38,487 INFO Worker Working
2020-10-21 14:43:13,565 INFO Worker initialized
2020-10-21 14:43:13,705 INFO Worker Working
2020-10-21 15:02:29,880 INFO Worker initialized
2020-10-21 15:02:30,034 INFO Worker Working
2020-10-22 09:19:55,703 INFO Worker initialized
2020-10-22 09:19:55,838 INFO Worker Working
2020-10-22 10:08:31,452 INFO Worker initialized
2020-10-22 10:08:31,583 INFO Worker Working
